Workbook

Sheet Hoja1
D1: 40 | G1: 40 | H1: 20 | I1: =IF(D1+G1+H1=100,"CORRECTO","INCORRECTO") -> CORRECTO
A2: ALUMNOS | B2: EXÁMENES | E2: PRÁCTICA | H2: ACTITUD | I2: ME | J2: MP | K2: NOTA FINAL | M2: RECUPERACIONES PRÁCTICAS | P2: RECUPERACIONES EXÁMENES
A3: ANTONIO PASCUAL | B3: 5.8 | C3: 7.4 | D3: 6 | E3: 7 | F3: 8 | G3: 5 | H3: 10 | I3: =AVERAGE(B3,C3) -> 6.6 | J3: =AVERAGE(E3:G3) -> 6.6666667 | K3: =D1*I3/100+G1*J3/100+H1*H3/100 -> 7.3066667 | L3: =IF(K3<5,"INSUFICIENTE",IF(K3<6,"SUFICIENTE",IF(K3<7,"BIEN",IF(K3<9,"NOTABLE","EXCELENTE")))) -> NOTABLE | M3: =IF(OR(E3<4,F3<4,G3<4),"SÍ NECESITA","NO NECESITA") -> NO NECESITA | P3: =IF(OR(B3<4,C3<4,D3<4),"SÍ NECESITA","NO NECESITA") -> NO NECESITA
A4: JAIME MARTÍNEZ | B4: 5.2 | C4: 6.9 | D4: 9 | E4: 9 | F4: 8 | G4: 7 | H4: 10 | I4: =AVERAGE(B4,C4) -> 6.05 | J4: =AVERAGE(E4:G4) -> 8 | K4: =I4*$D$1/100+J4*$G$1/100+$H$4*H1/100 -> 7.62 | L4: =IF(K4<5,"INSUFICIENTE",IF(K4<6,"SUFICIENTE",IF(K4<7,"BIEN",IF(K4<9,"NOTABLE","EXCELENTE")))) -> NOTABLE | M4: =IF(OR(E4<4,F4<4,G4<4),"SÍ NECESITA","NO NECESITA") -> NO NECESITA | P4: =IF(OR(B4<4,C4<4,D4<4),"SÍ NECESITA","NO NECESITA") -> NO NECESITA
A5: MANOLO CASTRO | B5: 4 | C5: 8 | D5: 3 | E5: 5 | F5: 6 | G5: 5 | H5: 7 | I5: =AVERAGE(B5,C5,D5) -> 5 | J5: =AVERAGE(E5:G5) -> 5.3333333 | K5: =I5*D1/100+J5*G1/100+H5*H1/100 -> 5.5333333 | L5: =IF(K5<5,"INSUFICIENTE",IF(K5<6,"SUFICIENTE",IF(K5<7,"BIEN",IF(K5<9,"NOTABLE","EXCELENTE")))) -> SUFICIENTE | M5: =IF(OR(E5<4,F5<4,G5<4),"SÍ NECESITA","NO NECESITA") -> NO NECESITA | P5: =IF(OR(B5<4,C5<4,D5<4),"SÍ NECESITA","NO NECESITA") -> SÍ NECESITA
A6: JAVIER LÓPEZ | B6: 7 | C6: 7 | D6: 8 | E6: 4 | F6: 2 | G6: 5 | H6: 9 | I6: =AVERAGE(B6,C6,D6) -> 7.3333333 | J6: =AVERAGE(E6:G6) -> 3.6666667 | K6: =I6*$D$1/100+J6*$G$1/100+$H$4*H3/100 -> 5.4 | L6: =IF(K6<5,"INSUFICIENTE",IF(K6<6,"SUFICIENTE",IF(K6<7,"BIEN",IF(K6<9,"NOTABLE","EXCELENTE")))) -> SUFICIENTE | M6: =IF(OR(E6<4,F6<4,G6<4),"SÍ NECESITA","NO NECESITA") -> SÍ NECESITA | P6: =IF(OR(B6<4,C6<4,D6<4),"SÍ NECESITA","NO NECESITA") -> NO NECESITA
A7: ADRIÁN SEVILLA | B7: 9 | C7: 10 | D7: 7 | E7: 7 | F7: 8 | G7: 8 | H7: 6 | I7: =AVERAGE(B7,C7,D7) -> 8.6666667 | J7: =AVERAGE(E7:G7) -> 7.6666667 | K7: =I7*$D$1/100+J7*$G$1/100+$H$4*H4/100 -> 7.5333333 | L7: =IF(K7<5,"INSUFICIENTE",IF(K7<6,"SUFICIENTE",IF(K7<7,"BIEN",IF(K7<9,"NOTABLE","EXCELENTE")))) -> NOTABLE | M7: =IF(OR(E7<4,F7<4,G7<4),"SÍ NECESITA","NO NECESITA") -> NO NECESITA | P7: =IF(OR(B7<4,C7<4,D7<4),"SÍ NECESITA","NO NECESITA") -> NO NECESITA
A8: ALEJANDRO SEGURA | B8: 6 | C8: 5 | D8: 8 | E8: 5 | F8: 9 | G8: 6 | H8: 8 | I8: =AVERAGE(B8,C8,D8) -> 6.3333333 | J8: =AVERAGE(E8:G8) -> 6.6666667 | K8: =I8*$D$1/100+J8*$G$1/100+$H$4*H5/100 -> 5.9 | L8: =IF(K8<5,"INSUFICIENTE",IF(K8<6,"SUFICIENTE",IF(K8<7,"BIEN",IF(K8<9,"NOTABLE","EXCELENTE")))) -> SUFICIENTE | M8: =IF(OR(E8<4,F8<4,G8<4),"SÍ NECESITA","NO NECESITA") -> NO NECESITA | P8: =IF(OR(B8<4,C8<4,D8<4),"SÍ NECESITA","NO NECESITA") -> NO NECESITA
A9: ESTRELLA CREMADES | B9: 7 | C9: 9 | D9: 8 | E9: 6 | F9: 8 | G9: 9 | H9: 4 | I9: =AVERAGE(B9,C9,D9) -> 8 | J9: =AVERAGE(E9:G9) -> 7.6666667 | K9: =I9*$D$1/100+J9*$G$1/100+$H$4*H6/100 -> 7.1666667 | L9: =IF(K9<5,"INSUFICIENTE",IF(K9<6,"SUFICIENTE",IF(K9<7,"BIEN",IF(K9<9,"NOTABLE","EXCELENTE")))) -> NOTABLE | M9: =IF(OR(E9<4,F9<4,G9<4),"SÍ NECESITA","NO NECESITA") -> NO NECESITA | P9: =IF(OR(B9<4,C9<4,D9<4),"SÍ NECESITA","NO NECESITA") -> NO NECESITA
A10: ROSA SEGURA | B10: 2 | C10: 1 | D10: 6 | E10: 3 | F10: 8 | G10: 5 | H10: 9 | I10: =AVERAGE(B10,C10,D10) -> 3 | J10: =AVERAGE(E10:G10) -> 5.3333333 | K10: =I10*$D$1/100+J10*$G$1/100+$H$4*H7/100 -> 3.9333333 | L10: =IF(K10<5,"INSUFICIENTE",IF(K10<6,"SUFICIENTE",IF(K10<7,"BIEN",IF(K10<9,"NOTABLE","EXCELENTE")))) -> INSUFICIENTE | M10: =IF(OR(E10<4,F10<4,G10<4),"SÍ NECESITA","NO NECESITA") -> SÍ NECESITA | P10: =IF(OR(B10<4,C10<4,D10<4),"SÍ NECESITA","NO NECESITA") -> SÍ NECESITA
A11: CRISTINA MARTÍNEZ | B11: 6 | C11: 6 | D11: 4 | E11: 5 | F11: 2 | G11: 1 | H11: 10 | I11: =AVERAGE(B11,C11,D11) -> 5.3333333 | J11: =AVERAGE(E11:G11) -> 2.6666667 | K11: =I11*$D$1/100+J11*$G$1/100+$H$4*H8/100 -> 4 | L11: =IF(K11<5,"INSUFICIENTE",IF(K11<6,"SUFICIENTE",IF(K11<7,"BIEN",IF(K11<9,"NOTABLE","EXCELENTE")))) -> INSUFICIENTE | M11: =IF(OR(E11<4,F11<4,G11<4),"SÍ NECESITA","NO NECESITA") -> SÍ NECESITA | P11: =IF(OR(B11<4,C11<4,D11<4),"SÍ NECESITA","NO NECESITA") -> NO NECESITA
A12: LUCÍA ROCA | B12: 8 | C12: 4 | D12: 7 | E12: 1 | F12: 8 | G12: 9 | H12: 10 | I12: =AVERAGE(B12,C12,D12) -> 6.3333333 | J12: =AVERAGE(E12:G12) -> 6 | K12: =I12*$D$1/100+J12*$G$1/100+$H$4*H9/100 -> 5.3333333 | L12: =IF(K12<5,"INSUFICIENTE",IF(K12<6,"SUFICIENTE",IF(K12<7,"BIEN",IF(K12<9,"NOTABLE","EXCELENTE")))) -> SUFICIENTE | M12: =IF(OR(E12<4,F12<4,G12<4),"SÍ NECESITA","NO NECESITA") -> SÍ NECESITA | P12: =IF(OR(B12<4,C12<4,D12<4),"SÍ NECESITA","NO NECESITA") -> NO NECESITA

Sheet Descripción
E5: Para sacar a los alumnos que tienen que recuperar las prácticas, he hecho esta formula =SI(O(E3<4;F3<4;G3<4);"SÍ NECESITA";"NO NECESITA")
E6: que significa que si en cada celda si es inferior a 4, tiene que salir "SÍ NECESITA" y si lo tiene aprobado "NO NECESITA".
C7: RECUPERACIONES
E9: Para las recuperaciones de los exámenes, he hecho lo mismo.
E13: Para sacar la nota final de los alumnos,
E14: hice esta formula =SI(K3<5;"INSUFICIENTE";SI(K3<6;"SUFICIENTE";SI(K3<7;"BIEN";SI(K3<9;"NOTABLE";"EXCELENTE"))))
E15: Si la nota es inferior a 5 tiene que salir INSUFICIENTE, si es inferior a 6 SUFICIENTE, si es inferior a 7 BIEN y si sale inferior a 9 NOTABLE y EXCELENTE

Sheet Diseños
EF231: TRUE
EL236: =RANDBETWEEN(1,31) -> 12
EK237: =IF(DZ231=TRUE,IF(EJ248<>"",EJ248,RANDBETWEEN(1,31)),"") | FB237: A
EF243: Tienes que sacar más de
EJ248: =IF(DZ231=TRUE,IF(EJ248<>"",EJ248,RANDBETWEEN(1,31)),"")
EI255: ¿LANZAR DADO?

Sheet BD
C7: Jugador | G7: Esqueleto 1 | J7: Esqueleto 2 | M7: Esqueleto 3
C9: Vida | D9: 20 | G9: Vida | H9: =RANDBETWEEN(5,14) -> 9 | J9: Vida | K9: =RANDBETWEEN(2,10) -> 7 | M9: Vida | N9: =RANDBETWEEN(1,5) -> 5
C10: Sin armas | D10: 2 | G10: Sin armas | J10: Sin armas | M10: Sin armas
C11: Daga | D11: 4 | G11: Daga | J11: Daga | M11: Daga
C12: Espada | D12: 6 | G12: Espada | H12: =RANDBETWEEN(3,9) -> 3 | J12: Espada | K12: =RANDBETWEEN(8,10) -> 10 | M12: Espada | N12: =RANDBETWEEN(7,9) -> 7
C13: Pistola | D13: 8 | G13: Pistola | H13: =RANDBETWEEN(4,8) -> 6 | J13: Pistola | K13: =RANDBETWEEN(6,9) -> 8 | M13: Pistola | N13: =RANDBETWEEN(8,10) -> 8
C16: Camisa | D16: 4
C17: Sombrero | D17: 2
C18: Pantalones | D18: 4
G21: Probabilidad de fallar | J21: Probabilidad de fallar | M21: Probabilidad de fallar
G22: =RANDBETWEEN(5,40) -> 16 | J22: =RANDBETWEEN(30,60) -> 58 | M22: =RANDBETWEEN(60,90) -> 82
B25: Taberna
B26: Cerveza | C26: 3 | D26: 5 | E26: 4
B27: Agua | C27: 1 | D27: 8 | E27: 2
B28: Arroz | C28: 6 | D28: 3 | E28: 9
B29: Pollo | C29: 10 | D29: 2 | E29: 20
C30: Precio | D30: Cantidad | E30: Vida

Sheet Calculo
XDW1: Calculo!A1
AF5: ATAQUES | AH5: ATAQUES | AK5: ATAQUES ENEMIGO
D8: COMBATE | AF8: (1) ATAQUE | AH8: (1) ATAQUE | AK8: (1) ATACAR
AF9: (1) ESQUIVAR | AH9: (1) ESQUIVAR | AK9: (1) ESQUIVAR
B10: CASILLA 149 --> | D10: ACTIVAR COMBATE | G10: VIDA ENEMIGO | I10: RESULTADO | K10: RESULTADO | AB10: 1 | AF10: (1) ATAQUE FUERTE | AH10: (1) ATAQUE FUERTE
D11: TRUE | AB11: ESQUIVAR
B12: CASILLA 147 --> | D12: ATAQUE | AB12: ATAQUE FUERTE
D13: FALSE | F13: =IF(D13=TRUE,6,IF(D13=FALSE,0)) -> 0 | G13: 20 | I13: =G13-F13 -> 20 | K13: =I13-F13 -> 20 | AF13: (2) ATAQUE | AH13: (2) ATAQUE | AK13: (2) ATACAR
B14: CASILLA 145 --> | D14: ESQUIVAR | AF14: (2) ESQUIVAR | AH14: (2) ESQUIVAR | AK14: (2) ESQUIVAR
D15: FALSE | F15: =IF(D15=TRUE,0,IF(D15=FALSE,0)) -> 0 | G15: 20 | I15: =G15-F15 -> 20 | K15: =I15-F15 -> 20 | AF15: (2) ATAQUE FUERTE | AH15: (2) ATAQUE FUERTE
B16: CASILLA 148 --> | D16: ATAQUE FUERTE
D17: FALSE | F17: =IF(D17=TRUE,20,IF(D17=FALSE,0)) -> 0 | G17: 20 | I17: =G17-F17 -> 20 | K17: =I17-F17 -> 20
AF18: (3) ATAQUE | AH18: (3) ATAQUE | AK18: (3) ATACAR
AF19: (3) ESQUIVAR | AH19: (3) ESQUIVAR | AK19: (3) ESQUIVAR
AF20: (3) ATAQUE FUERTE | AH20: (3) ATAQUE FUERTE
J23: =I13+I15+I17/3 -> 46.666667 | AF23: (4) ATAQUE | AH23: (4) ATAQUE | AK23: (4) ATACAR
AF24: (4) ESQUIVAR | AH24: (4) ESQUIVAR | AK24: (4) ESQUIVAR
AF25: (4) ATAQUE FUERTE | AH25: (4) ATAQUE FUERTE
AF28: (5) ATAQUE | AH28: (5) ATAQUE | AK28: (5) ATACAR | XDR28: PVE 1 | XEH28: PVE 3
AF29: (5) ESQUIVAR | AH29: (5) ESQUIVAR | AK29: (5) ESQUIVAR
AF30: (5) ATAQUE FUERTE | AH30: (5) ATAQUE FUERTE
N31: …...............
AF33: (6) ATAQUE | AH33: (6) ATAQUE | AK33: (6) ATACAR
AF34: (6) ESQUIVAR | AH34: (6) ESQUIVAR | AK34: (6) ESQUIVAR
AF35: (6) ATAQUE FUERTE | AH35: (6) ATAQUE FUERTE | XDY35: VIDA JUGADOR | XEO35: VIDA JUGADOR
XDR36: FALSE | XDT36: a1 | XDU36: =VLOOKUP(PVE!$CT$7,$XDO$40:$XDP$40,2,FALSE) -> 2 | XDV36: =IF(XDR36=TRUE,1,0) -> 0 | XDW36: =IF(XDR36=TRUE,IF(XDW36>0,XDW36,XDU36*XDV36),0) -> 0 | XDY36: =18-SUM(XDW36:XDW44) -> 18 | XEH36: FALSE | XEJ36: a1 | XEK36: =VLOOKUP(PVE!$CT$7,$XDO$40:$XDP$40,2,FALSE) -> 2 | XEL36: =IF(XEH36=TRUE,1,0) -> 0 | XEM36: =IF(XEH36=TRUE,IF(XEM36>0,XEM36,XEK36*XEL36),0) -> 0 | XEO36: =18-SUM(XEM36:XEM44) -> 18
XDR37: FALSE | XDT37: a2 | XDU37: =VLOOKUP(PVE!$CT$7,$XDO$40:$XDP$40,2,FALSE) -> 2 | XDV37: =IF(XDR37=TRUE,1,0) -> 0 | XDW37: =IF(XDR37=TRUE,IF(XDW37>0,XDW37,XDU37*XDV37),0) -> 0 | XEH37: FALSE | XEJ37: a2 | XEK37: =VLOOKUP(PVE!$CT$7,$XDO$40:$XDP$40,2,FALSE) -> 2 | XEL37: =IF(XEH37=TRUE,1,0) -> 0 | XEM37: =IF(XEH37=TRUE,IF(XEM37>0,XEM37,XEK37*XEL37),0) -> 0
AF38: (7) ATAQUE | AH38: (7) ATAQUE | AK38: (7) ATACAR | XDR38: FALSE | XDT38: a3 | XDU38: =VLOOKUP(PVE!$CT$7,$XDO$40:$XDP$40,2,FALSE) -> 2 | XDV38: =IF(XDR38=TRUE,1,0) -> 0 | XDW38: =IF(XDR38=TRUE,IF(XDW38>0,XDW38,XDU38*XDV38),0) -> 0 | XEH38: FALSE | XEJ38: a3 | XEK38: =VLOOKUP(PVE!$CT$7,$XDO$40:$XDP$40,2,FALSE) -> 2 | XEL38: =IF(XEH38=TRUE,1,0) -> 0 | XEM38: =IF(XEH38=TRUE,IF(XEM38>0,XEM38,XEK38*XEL38),0) -> 0
AF39: (7) ESQUIVAR | AH39: (7) ESQUIVAR | AK39: (7) ESQUIVAR | XDR39: FALSE | XDT39: a4 | XDU39: =VLOOKUP(PVE!$CT$7,$XDO$40:$XDP$40,2,FALSE) -> 2 | XDV39: =IF(XDR39=TRUE,1,0) -> 0 | XDW39: =IF(XDR39=TRUE,IF(XDW39>0,XDW39,XDU39*XDV39),0) -> 0 | XEH39: FALSE | XEJ39: a4 | XEK39: =VLOOKUP(PVE!$CT$7,$XDO$40:$XDP$40,2,FALSE) -> 2 | XEL39: =IF(XEH39=TRUE,1,0) -> 0 | XEM39: =IF(XEH39=TRUE,IF(XEM39>0,XEM39,XEK39*XEL39),0) -> 0
AF40: (7) ATAQUE FUERTE | AH40: (7) ATAQUE FUERTE | AK40: (7) ATAQUE FUERTE | XDO40: Esqueleto | XDP40: 2 | XDR40: FALSE | XDT40: a5 | XDU40: =VLOOKUP(PVE!$CT$7,$XDO$40:$XDP$40,2,FALSE) -> 2 | XDV40: =IF(XDR40=TRUE,1,0) -> 0 | XDW40: =IF(XDR40=TRUE,IF(XDW40>0,XDW40,XDU40*XDV40),0) -> 0 | XEE40: Vikingo | XEF40: 2 | XEH40: FALSE | XEJ40: a5 | XEK40: =VLOOKUP(PVE!$CT$7,$XDO$40:$XDP$40,2,FALSE) -> 2 | XEL40: =IF(XEH40=TRUE,1,0) -> 0 | XEM40: =IF(XEH40=TRUE,IF(XEM40>0,XEM40,XEK40*XEL40),0) -> 0
XDR41: FALSE | XDT41: a6 | XDU41: =VLOOKUP(PVE!$CT$7,$XDO$40:$XDP$40,2,FALSE) -> 2 | XDV41: =IF(XDR41=TRUE,1,0) -> 0 | XDW41: =IF(XDR41=TRUE,IF(XDW41>0,XDW41,XDU41*XDV41),0) -> 0 | XEH41: FALSE | XEJ41: a6 | XEK41: =VLOOKUP(PVE!$CT$7,$XDO$40:$XDP$40,2,FALSE) -> 2 | XEL41: =IF(XEH41=TRUE,1,0) -> 0 | XEM41: =IF(XEH41=TRUE,IF(XEM41>0,XEM41,XEK41*XEL41),0) -> 0
XDR42: FALSE | XDT42: a7 | XDU42: =VLOOKUP(PVE!$CT$7,$XDO$40:$XDP$40,2,FALSE) -> 2 | XDV42: =IF(XDR42=TRUE,1,0) -> 0 | XDW42: =IF(XDR42=TRUE,IF(XDW42>0,XDW42,XDU42*XDV42),0) -> 0 | XEH42: FALSE | XEJ42: a7 | XEK42: =VLOOKUP(PVE!$CT$7,$XDO$40:$XDP$40,2,FALSE) -> 2 | XEL42: =IF(XEH42=TRUE,1,0) -> 0 | XEM42: =IF(XEH42=TRUE,IF(XEM42>0,XEM42,XEK42*XEL42),0) -> 0
AF43: (8) ATAQUE | AH43: (8) ATAQUE | XDR43: FALSE | XDT43: a8 | XDU43: =VLOOKUP(PVE!$CT$7,$XDO$40:$XDP$40,2,FALSE) -> 2 | XDV43: =IF(XDR43=TRUE,1,0) -> 0 | XDW43: =IF(XDR43=TRUE,IF(XDW43>0,XDW43,XDU43*XDV43),0) -> 0 | XEH43: FALSE | XEJ43: a8 | XEK43: =VLOOKUP(PVE!$CT$7,$XDO$40:$XDP$40,2,FALSE) -> 2 | XEL43: =IF(XEH43=TRUE,1,0) -> 0 | XEM43: =IF(XEH43=TRUE,IF(XEM43>0,XEM43,XEK43*XEL43),0) -> 0
AF44: (8) ESQUIVAR | AH44: (8) ESQUIVAR | XDR44: FALSE | XDT44: a9 | XDU44: =VLOOKUP(PVE!$CT$7,$XDO$40:$XDP$40,2,FALSE) -> 2 | XDV44: =IF(XDR44=TRUE,1,0) -> 0 | XDW44: =IF(XDR44=TRUE,IF(XDW44>0,XDW44,XDU44*XDV44),0) -> 0 | XEH44: FALSE | XEJ44: a9 | XEK44: =VLOOKUP(PVE!$CT$7,$XDO$40:$XDP$40,2,FALSE) -> 2 | XEL44: =IF(XEH44=TRUE,1,0) -> 0 | XEM44: =IF(XEH44=TRUE,IF(XEM44>0,XEM44,XEK44*XEL44),0) -> 0
AF45: (8) ATAQUE FUERTE | AH45: (8) ATAQUE FUERTE
P48: TUTORIAL | V48: PVE 3 | AF48: (9) ATAQUE | AH48: (9) ATAQUE | XDY48: VIDA ENEMIGO | XEO48: VIDA ENEMIGO
AF49: (9) ESQUIVAR | AH49: (9) ESQUIVAR | XDR49: FALSE | XDT49: a1 | XDU49: =VLOOKUP(PVE!$G$9,XDO52:XDP54,2,FALSE) -> 2 | XDV49: =IF(XDR49=TRUE,1,0) -> 0 | XDW49: =IF(XDR49=TRUE,IF(XDW49>0,XDW49,XDU49*XDV49),0) -> 0 | XDY49: =18-SUM(XDW49:XDW57) -> 18 | XEH49: FALSE | XEJ49: a1 | XEK49: =VLOOKUP(PVE!$G$9,$XDO$83:$XDP$85,2,FALSE) -> 2 | XEL49: =IF(XEH49=TRUE,1,0) -> 0 | XEM49: =IF(XEH49=TRUE,IF(XEM49>0,XEM49,XEK49*XEL49),0) -> 0 | XEO49: =18-SUM(XEM49:XEM57) -> 18
Q50: Jugador | R50: Práctica | S50: DAÑO | T50: DAÑO | X50: Jugador | Y50: Enemigo5 | AF50: (9) ATAQUE FUERTE | AH50: (9) ATAQUE FUERTE | XDR50: FALSE | XDT50: a2 | XDU50: =VLOOKUP(PVE!$G$9,$XDO$52:$XDP$54,2,FALSE) -> 2 | XDV50: =IF(XDR50=TRUE,1,0) -> 0 | XDW50: =IF(XDR50=TRUE,IF(XDW50>0,XDW50,XDU50*XDV50),0) -> 0 | XEH50: FALSE | XEJ50: a2 | XEK50: =VLOOKUP(PVE!$G$9,$XDO$83:$XDP$85,2,FALSE) -> 2 | XEL50: =IF(XEH50=TRUE,1,0) -> 0 | XEM50: =IF(XEH50=TRUE,IF(XEM50>0,XEM50,XEK50*XEL50),0) -> 0
P51: Vida | Q51: =' Tutorial combate'!AN18 -> 20 | R51: =' Tutorial combate'!CO25 -> 20 | S51: =RANDBETWEEN(0,10) -> 2 | T51: =' Tutorial combate'!CQ25 -> 0 | W51: Vida | X51: =PVE!AF18 -> 0 | Y51: 30 | XDR51: FALSE | XDT51: a3 | XDU51: =VLOOKUP(PVE!$G$9,$XDO$52:$XDP$54,2,FALSE) -> 2 | XDV51: =IF(XDR51=TRUE,1,0) -> 0 | XDW51: =IF(XDR51=TRUE,IF(XDW51>0,XDW51,XDU51*XDV51),0) -> 0 | XEH51: FALSE | XEJ51: a3 | XEK51: =VLOOKUP(PVE!$G$9,$XDO$83:$XDP$85,2,FALSE) -> 2 | XEL51: =IF(XEH51=TRUE,1,0) -> 0 | XEM51: =IF(XEH51=TRUE,IF(XEM51>0,XEM51,XEK51*XEL51),0) -> 0
N52: 0 | P52: Ataque | Q52: =RANDBETWEEN(0,20) -> 18 | R52: 0 | S52: 0 | T52: 0 | W52: Ataque | X52: =RANDBETWEEN(1,20) -> 7 | Y52: =RANDBETWEEN(1,20) -> 13 | XDO52: Puñetazo | XDP52: 2 | XDR52: FALSE | XDT52: a4 | XDU52: =VLOOKUP(PVE!$G$9,$XDO$52:$XDP$54,2,FALSE) -> 2 | XDV52: =IF(XDR52=TRUE,1,0) -> 0 | XDW52: =IF(XDR52=TRUE,IF(XDW52>0,XDW52,XDU52*XDV52),0) -> 0 | XEE52: Puñetazo | XEF52: 2 | XEH52: FALSE | XEJ52: a4 | XEK52: =VLOOKUP(PVE!$G$9,$XDO$83:$XDP$85,2,FALSE) -> 2 | XEL52: =IF(XEH52=TRUE,1,0) -> 0 | XEM52: =IF(XEH52=TRUE,IF(XEM52>0,XEM52,XEK52*XEL52),0) -> 0
...

Sheet 1º
BE11: ¡Gracias por adquirir Pirate Valley©!
BE15: Estás a punto de comenzar un videojuego de combate por turnos dónde he escondido
BE17: varias referencias donde te animo a encontrar todas, ¿serás capaz de encontrarlas?
BE50: Por favor, lee este acuerdo en su totalidad. Debes aceptar las condiciones del
BE52: Acuerdo de Suscripción a Steam para continuar.
DO55: ACEPTO

Sheet 2º
BE50: Por favor, lee este acuerdo en su totalidad. Debes aceptar las condiciones del
BE52: Acuerdo de Suscripción a Steam para continuar.
EN54: º
DO55: ACEPTO

Sheet Hoja3

Sheet Escenario prueba
AG3: 20 | DV3: 20

Sheet Menú Principal
Q28: TUTORIAL
Q37: MODO COMBATE

Sheet Menú Noche
Q28: TUTORIAL
Q37: MODO COMBATE

Sheet PVE
AA4: =Calculo!XDY36 -> 18
CT7: Esqueleto
CC8: =Calculo!XDY49 -> 18
G9: Puñetazo
DW14: =CC8 -> 18
D37: Continuar | CN37: Continuar

Sheet Hoja4
Z22: Hoja5!A1
BN25: Dale click al cómic que está mal puesto.

Sheet Hoja5

Sheet Introducción1

Sheet Hoja2

Sheet Introducción2

Sheet Introducción3

Sheet PVE2
AL2: =FV19 -> 18 | CO2: =FV32 -> 25
G12: Puñetazo
FV18: VIDA JUGADOR
FO19: FALSE | FQ19: a1 | FR19: =VLOOKUP(F24,FL23:FM23,2,FALSE) -> 3 | FS19: =IF(FO19=TRUE,1,0) -> 0 | FT19: =IF(FO19=TRUE,IF(FT19>0,FT19,FR19*FS19),0) -> 0 | FV19: =18-SUM(FT19:FT27) -> 18
FO20: FALSE | FQ20: a2 | FR20: =VLOOKUP($F$24,$FL$23:$FM$23,2,FALSE) -> 3 | FS20: =IF(FO20=TRUE,1,0) -> 0 | FT20: =IF(FO20=TRUE,IF(FT20>0,FT20,FR20*FS20),0) -> 0
FO21: FALSE | FQ21: a3 | FR21: =VLOOKUP($F$24,$FL$23:$FM$23,2,FALSE) -> 3 | FS21: =IF(FO21=TRUE,1,0) -> 0 | FT21: =IF(FO21=TRUE,IF(FT21>0,FT21,FR21*FS21),0) -> 0
FO22: FALSE | FQ22: a4 | FR22: =VLOOKUP($F$24,$FL$23:$FM$23,2,FALSE) -> 3 | FS22: =IF(FO22=TRUE,1,0) -> 0 | FT22: =IF(FO22=TRUE,IF(FT22>0,FT22,FR22*FS22),0) -> 0
FL23: Un pirata muy reconocible | FM23: 3 | FO23: FALSE | FQ23: a5 | FR23: =VLOOKUP($F$24,$FL$23:$FM$23,2,FALSE) -> 3 | FS23: =IF(FO23=TRUE,1,0) -> 0 | FT23: =IF(FO23=TRUE,IF(FT23>0,FT23,FR23*FS23),0) -> 0
F24: Un pirata muy reconocible | FO24: FALSE | FQ24: a6 | FR24: =VLOOKUP($F$24,$FL$23:$FM$23,2,FALSE) -> 3 | FS24: =IF(FO24=TRUE,1,0) -> 0 | FT24: =IF(FO24=TRUE,IF(FT24>0,FT24,FR24*FS24),0) -> 0
FO25: FALSE | FQ25: a7 | FR25: =VLOOKUP($F$24,$FL$23:$FM$23,2,FALSE) -> 3 | FS25: =IF(FO25=TRUE,1,0) -> 0 | FT25: =IF(FO25=TRUE,IF(FT25>0,FT25,FR25*FS25),0) -> 0
FO26: FALSE | FQ26: a8 | FR26: =VLOOKUP($F$24,$FL$23:$FM$23,2,FALSE) -> 3 | FS26: =IF(FO26=TRUE,1,0) -> 0 | FT26: =IF(FO26=TRUE,IF(FT26>0,FT26,FR26*FS26),0) -> 0
FO27: FALSE | FQ27: a9 | FR27: =VLOOKUP($F$24,$FL$23:$FM$23,2,FALSE) -> 3 | FS27: =IF(FO27=TRUE,1,0) -> 0 | FT27: =IF(FO27=TRUE,IF(FT27>0,FT27,FR27*FS27),0) -> 0
FV31: VIDA ENEMIGO
FO32: FALSE | FQ32: a1 | FR32: =VLOOKUP(G12,FL35:FM37,2,FALSE) -> 3 | FS32: =IF(FO32=TRUE,1,0) -> 0 | FT32: =IF(FO32=TRUE,IF(FT32>0,FT32,FR32*FS32),0) -> 0 | FV32: =25-SUM(FT32:FT40) -> 25
FO33: FALSE | FQ33: a2 | FR33: =VLOOKUP($G$12,$FL$35:$FM$37,2,FALSE) -> 3 | FS33: =IF(FO33=TRUE,1,0) -> 0 | FT33: =IF(FO33=TRUE,IF(FT33>0,FT33,FR33*FS33),0) -> 0
FO34: FALSE | FQ34: a3 | FR34: =VLOOKUP($G$12,$FL$35:$FM$37,2,FALSE) -> 3 | FS34: =IF(FO34=TRUE,1,0) -> 0 | FT34: =IF(FO34=TRUE,IF(FT34>0,FT34,FR34*FS34),0) -> 0
FL35: Puñetazo | FM35: 3 | FO35: FALSE | FQ35: a4 | FR35: =VLOOKUP($G$12,$FL$35:$FM$37,2,FALSE) -> 3 | FS35: =IF(FO35=TRUE,1,0) -> 0 | FT35: =IF(FO35=TRUE,IF(FT35>0,FT35,FR35*FS35),0) -> 0
FL36: Espadazo | FM36: 9 | FO36: FALSE | FQ36: a5 | FR36: =VLOOKUP($G$12,$FL$35:$FM$37,2,FALSE) -> 3 | FS36: =IF(FO36=TRUE,1,0) -> 0 | FT36: =IF(FO36=TRUE,IF(FT36>0,FT36,FR36*FS36),0) -> 0
FL37: CRÍTICO | FM37: 1 | FO37: FALSE | FQ37: a6 | FR37: =VLOOKUP($G$12,$FL$35:$FM$37,2,FALSE) -> 3 | FS37: =IF(FO37=TRUE,1,0) -> 0 | FT37: =IF(FO37=TRUE,IF(FT37>0,FT37,FR37*FS37),0) -> 0
FO38: FALSE | FQ38: a7 | FR38: =VLOOKUP($G$12,$FL$35:$FM$37,2,FALSE) -> 3 | FS38: =IF(FO38=TRUE,1,0) -> 0 | FT38: =IF(FO38=TRUE,IF(FT38>0,FT38,FR38*FS38),0) -> 0
BB39: =IF(OR(,CO2<1),"Continuar","") | CC39: =IF(OR(,AL2<1),"Continuar","") | FO39: FALSE | FQ39: a8 | FR39: =VLOOKUP($G$12,$FL$35:$FM$37,2,FALSE) -> 3 | FS39: =IF(FO39=TRUE,1,0) -> 0 | FT39: =IF(FO39=TRUE,IF(FT39>0,FT39,FR39*FS39),0) -> 0
FO40: FALSE | FQ40: a9 | FR40: =VLOOKUP($G$12,$FL$35:$FM$37,2,FALSE) -> 3 | FS40: =IF(FO40=TRUE,1,0) -> 0 | FT40: =IF(FO40=TRUE,IF(FT40>0,FT40,FR40*FS40),0) -> 0
FP82: =SUM(FP10:FP81) -> 0 | FR82: =SUM(FR10:FR81) -> 54 | FU82: =SUM(FU10:FU81) -> 0 | FV82: =SUM(FV10:FV81) -> 43 | FW82: =SUM(FW10:FW81) -> 0 | FY82: =SUM(FY10:FY81) -> 0

Sheet PVE3
AL2: =FG14 -> 18
CP3: =FG27 -> 30
F12: Puñetazo | W12: Vikingo
FG13: VIDA JUGADOR
EZ14: FALSE | FB14: a1 | FC14: =VLOOKUP(W12,EW18:EX18,2,FALSE) -> 3 | FD14: =IF(EZ14=TRUE,1,0) -> 0 | FE14: =IF(EZ14=TRUE,IF(FE14>0,FE14,FC14*FD14),0) -> 0 | FG14: =18-SUM(FE14:FE22) -> 18
EZ15: FALSE | FB15: a2 | FC15: =VLOOKUP($W$12,$EW$18:$EX$18,2,FALSE) -> 3 | FD15: =IF(EZ15=TRUE,1,0) -> 0 | FE15: =IF(EZ15=TRUE,IF(FE15>0,FE15,FC15*FD15),0) -> 0
EZ16: FALSE | FB16: a3 | FC16: =VLOOKUP($W$12,$EW$18:$EX$18,2,FALSE) -> 3 | FD16: =IF(EZ16=TRUE,1,0) -> 0 | FE16: =IF(EZ16=TRUE,IF(FE16>0,FE16,FC16*FD16),0) -> 0
EZ17: FALSE | FB17: a4 | FC17: =VLOOKUP($W$12,$EW$18:$EX$18,2,FALSE) -> 3 | FD17: =IF(EZ17=TRUE,1,0) -> 0 | FE17: =IF(EZ17=TRUE,IF(FE17>0,FE17,FC17*FD17),0) -> 0
EW18: Vikingo | EX18: 3 | EZ18: FALSE | FB18: a5 | FC18: =VLOOKUP($W$12,$EW$18:$EX$18,2,FALSE) -> 3 | FD18: =IF(EZ18=TRUE,1,0) -> 0 | FE18: =IF(EZ18=TRUE,IF(FE18>0,FE18,FC18*FD18),0) -> 0
EZ19: FALSE | FB19: a6 | FC19: =VLOOKUP($W$12,$EW$18:$EX$18,2,FALSE) -> 3 | FD19: =IF(EZ19=TRUE,1,0) -> 0 | FE19: =IF(EZ19=TRUE,IF(FE19>0,FE19,FC19*FD19),0) -> 0
EZ20: FALSE | FB20: a7 | FC20: =VLOOKUP($W$12,$EW$18:$EX$18,2,FALSE) -> 3 | FD20: =IF(EZ20=TRUE,1,0) -> 0 | FE20: =IF(EZ20=TRUE,IF(FE20>0,FE20,FC20*FD20),0) -> 0
EZ21: FALSE | FB21: a8 | FC21: =VLOOKUP($W$12,$EW$18:$EX$18,2,FALSE) -> 3 | FD21: =IF(EZ21=TRUE,1,0) -> 0 | FE21: =IF(EZ21=TRUE,IF(FE21>0,FE21,FC21*FD21),0) -> 0
EZ22: FALSE | FB22: a9 | FC22: =VLOOKUP($W$12,$EW$18:$EX$18,2,FALSE) -> 3 | FD22: =IF(EZ22=TRUE,1,0) -> 0 | FE22: =IF(EZ22=TRUE,IF(FE22>0,FE22,FC22*FD22),0) -> 0
FG26: VIDA ENEMIGO
EZ27: FALSE | FB27: a1 | FC27: =VLOOKUP(F12,EW30:EX32,2,FALSE) -> 3 | FD27: =IF(EZ27=TRUE,1,0) -> 0 | FE27: =IF(EZ27=TRUE,IF(FE27>0,FE27,FC27*FD27),0) -> 0 | FG27: =30-SUM(FE27:FE35) -> 30
EZ28: FALSE | FB28: a2 | FC28: =VLOOKUP($F$12,$EW$30:$EX$32,2,FALSE) -> 3 | FD28: =IF(EZ28=TRUE,1,0) -> 0 | FE28: =IF(EZ28=TRUE,IF(FE28>0,FE28,FC28*FD28),0) -> 0
EZ29: FALSE | FB29: a3 | FC29: =VLOOKUP($F$12,$EW$30:$EX$32,2,FALSE) -> 3 | FD29: =IF(EZ29=TRUE,1,0) -> 0 | FE29: =IF(EZ29=TRUE,IF(FE29>0,FE29,FC29*FD29),0) -> 0
EW30: Puñetazo | EX30: 3 | EZ30: FALSE | FB30: a4 | FC30: =VLOOKUP($F$12,$EW$30:$EX$32,2,FALSE) -> 3 | FD30: =IF(EZ30=TRUE,1,0) -> 0 | FE30: =IF(EZ30=TRUE,IF(FE30>0,FE30,FC30*FD30),0) -> 0
EW31: Espadazo | EX31: 9 | EZ31: FALSE | FB31: a5 | FC31: =VLOOKUP($F$12,$EW$30:$EX$32,2,FALSE) -> 3 | FD31: =IF(EZ31=TRUE,1,0) -> 0 | FE31: =IF(EZ31=TRUE,IF(FE31>0,FE31,FC31*FD31),0) -> 0
EW32: CRÍTICO | EX32: 1 | EZ32: FALSE | FB32: a6 | FC32: =VLOOKUP($F$12,$EW$30:$EX$32,2,FALSE) -> 3 | FD32: =IF(EZ32=TRUE,1,0) -> 0 | FE32: =IF(EZ32=TRUE,IF(FE32>0,FE32,FC32*FD32),0) -> 0 | FO32: FALSE
AZ33: =IF(OR(AL2<1),"Continuar","") | BW33: =IF(OR(CP3<1),"Continuar","") | EZ33: FALSE | FB33: a7 | FC33: =VLOOKUP($F$12,$EW$30:$EX$32,2,FALSE) -> 3 | FD33: =IF(EZ33=TRUE,1,0) -> 0 | FE33: =IF(EZ33=TRUE,IF(FE33>0,FE33,FC33*FD33),0) -> 0
EZ34: FALSE | FB34: a8 | FC34: =VLOOKUP($F$12,$EW$30:$EX$32,2,FALSE) -> 3 | FD34: =IF(EZ34=TRUE,1,0) -> 0 | FE34: =IF(EZ34=TRUE,IF(FE34>0,FE34,FC34*FD34),0) -> 0
EZ35: FALSE | FB35: a9 | FC35: =VLOOKUP($F$12,$EW$30:$EX$32,2,FALSE) -> 3 | FD35: =IF(EZ35=TRUE,1,0) -> 0 | FE35: =IF(EZ35=TRUE,IF(FE35>0,FE35,FC35*FD35),0) -> 0

Sheet PVE4
AO32: Si has ganado | BX32: Si has muerto
AO34: dale click aquí | BX34: dale click aquí

Sheet FINAL BOSS
A1: =GB9 -> 28 | CV1: =GB22 -> 40
C8: Espadazo | CW8: Final Boss | GB8: VIDA JUGADOR
FU9: FALSE | FW9: a1 | FX9: =VLOOKUP(CW8,FR13:FS13,2,FALSE) -> 7 | FY9: =IF(FU9=TRUE,1,0) -> 0 | FZ9: =IF(FU9=TRUE,IF(FZ9>0,FZ9,FX9*FY9),0) -> 0 | GB9: =28-SUM(FZ9:FZ17) -> 28
FU10: FALSE | FW10: a2 | FX10: =VLOOKUP($CW$8,$FR$13:$FS$13,2,FALSE) -> 7 | FY10: =IF(FU10=TRUE,1,0) -> 0 | FZ10: =IF(FU10=TRUE,IF(FZ10>0,FZ10,FX10*FY10),0) -> 0
FU11: FALSE | FW11: a3 | FX11: =VLOOKUP($CW$8,$FR$13:$FS$13,2,FALSE) -> 7 | FY11: =IF(FU11=TRUE,1,0) -> 0 | FZ11: =IF(FU11=TRUE,IF(FZ11>0,FZ11,FX11*FY11),0) -> 0
FU12: FALSE | FW12: a4 | FX12: =VLOOKUP($CW$8,$FR$13:$FS$13,2,FALSE) -> 7 | FY12: =IF(FU12=TRUE,1,0) -> 0 | FZ12: =IF(FU12=TRUE,IF(FZ12>0,FZ12,FX12*FY12),0) -> 0
FR13: Final Boss | FS13: 7 | FU13: FALSE | FW13: a5 | FX13: =VLOOKUP($CW$8,$FR$13:$FS$13,2,FALSE) -> 7 | FY13: =IF(FU13=TRUE,1,0) -> 0 | FZ13: =IF(FU13=TRUE,IF(FZ13>0,FZ13,FX13*FY13),0) -> 0
FU14: FALSE | FW14: a6 | FX14: =VLOOKUP($CW$8,$FR$13:$FS$13,2,FALSE) -> 7 | FY14: =IF(FU14=TRUE,1,0) -> 0 | FZ14: =IF(FU14=TRUE,IF(FZ14>0,FZ14,FX14*FY14),0) -> 0
FU15: FALSE | FW15: a7 | FX15: =VLOOKUP($CW$8,$FR$13:$FS$13,2,FALSE) -> 7 | FY15: =IF(FU15=TRUE,1,0) -> 0 | FZ15: =IF(FU15=TRUE,IF(FZ15>0,FZ15,FX15*FY15),0) -> 0
FU16: FALSE | FW16: a8 | FX16: =VLOOKUP($CW$8,$FR$13:$FS$13,2,FALSE) -> 7 | FY16: =IF(FU16=TRUE,1,0) -> 0 | FZ16: =IF(FU16=TRUE,IF(FZ16>0,FZ16,FX16*FY16),0) -> 0
FU17: FALSE | FW17: a9 | FX17: =VLOOKUP($CW$8,$FR$13:$FS$13,2,FALSE) -> 7 | FY17: =IF(FU17=TRUE,1,0) -> 0 | FZ17: =IF(FU17=TRUE,IF(FZ17>0,FZ17,FX17*FY17),0) -> 0
CO20: º
GB21: VIDA ENEMIGO
FU22: FALSE | FW22: a1 | FX22: =VLOOKUP(C8,FR25:FS27,2,FALSE) -> 7 | FY22: =IF(FU22=TRUE,1,0) -> 0 | FZ22: =IF(FU22=TRUE,IF(FZ22>0,FZ22,FX22*FY22),0) -> 0 | GB22: =40-SUM(FZ22:FZ30) -> 40
FU23: FALSE | FW23: a2 | FX23: =VLOOKUP($C$8,$FR$25:$FS$27,2,FALSE) -> 7 | FY23: =IF(FU23=TRUE,1,0) -> 0 | FZ23: =IF(FU23=TRUE,IF(FZ23>0,FZ23,FX23*FY23),0) -> 0
FU24: FALSE | FW24: a3 | FX24: =VLOOKUP($C$8,$FR$25:$FS$27,2,FALSE) -> 7 | FY24: =IF(FU24=TRUE,1,0) -> 0 | FZ24: =IF(FU24=TRUE,IF(FZ24>0,FZ24,FX24*FY24),0) -> 0
FR25: Puñetazo | FS25: 2 | FU25: FALSE | FW25: a4 | FX25: =VLOOKUP($C$8,$FR$25:$FS$27,2,FALSE) -> 7 | FY25: =IF(FU25=TRUE,1,0) -> 0 | FZ25: =IF(FU25=TRUE,IF(FZ25>0,FZ25,FX25*FY25),0) -> 0
FR26: Espadazo | FS26: 7 | FU26: FALSE | FW26: a5 | FX26: =VLOOKUP($C$8,$FR$25:$FS$27,2,FALSE) -> 7 | FY26: =IF(FU26=TRUE,1,0) -> 0 | FZ26: =IF(FU26=TRUE,IF(FZ26>0,FZ26,FX26*FY26),0) -> 0
FR27: CRÍTICO | FS27: 0 | FU27: FALSE | FW27: a6 | FX27: =VLOOKUP($C$8,$FR$25:$FS$27,2,FALSE) -> 7 | FY27: =IF(FU27=TRUE,1,0) -> 0 | FZ27: =IF(FU27=TRUE,IF(FZ27>0,FZ27,FX27*FY27),0) -> 0
FU28: FALSE | FW28: a7 | FX28: =VLOOKUP($C$8,$FR$25:$FS$27,2,FALSE) -> 7 | FY28: =IF(FU28=TRUE,1,0) -> 0 | FZ28: =IF(FU28=TRUE,IF(FZ28>0,FZ28,FX28*FY28),0) -> 0
FU29: FALSE | FW29: a8 | FX29: =VLOOKUP($C$8,$FR$25:$FS$27,2,FALSE) -> 7 | FY29: =IF(FU29=TRUE,1,0) -> 0 | FZ29: =IF(FU29=TRUE,IF(FZ29>0,FZ29,FX29*FY29),0) -> 0
FU30: FALSE | FW30: a9 | FX30: =VLOOKUP($C$8,$FR$25:$FS$27,2,FALSE) -> 7 | FY30: =IF(FU30=TRUE,1,0) -> 0 | FZ30: =IF(FU30=TRUE,IF(FZ30>0,FZ30,FX30*FY30),0) -> 0
BO32: =IF(OR(CV1<1),"Continuar","")

Sheet YW
AI22: PVE2'!A1 | XBS22: PVE3'!A1
Z33: Volver al menú | XBB33: Volver al menú
BH1048544: PVE5'!A1 | XBZ1048544: FINAL BOSS'!A1
XAY1048555: Volver al menú
AC1048557: Volver al menú

Sheet YD
AL30: Volver al menú

Sheet T

Sheet Tutorial
Q10: Tutorial2!A1

Sheet Tutorial2

Sheet Tutorial3
BG19: ¿PREPARADO?
AH61: º

Sheet Tutorial4
BG20: ¿LISTO?

Sheet Tutorial5
BG20: ¡¡ A LUCHAR !!

Sheet  Tutorial combate
F3: ACCIÓN
AN18: 20
GJ21: CO25;ALEATORIO.ENTRE(0;20)
CO25: 20
CD111: 20

Sheet COMBATE
F9: Puñetazo | Y9: =FB14 -> 20
FB13: VIDA JUGADOR
FB14: =20-SUM(EZ14:EZ22) -> 20
BZ16: =FB27 -> 20
ER18: Un pirata muy reconocible | ES18: 3
GJ21: CO25;ALEATORIO.ENTRE(0;20)
FB26: VIDA ENEMIGO
EU27: FALSE | EW27: a1 | EX27: =VLOOKUP(F9,ER30:ES32,2,FALSE) -> 2 | EY27: =IF(EU27=TRUE,1,0) -> 0 | EZ27: =IF(EU27=TRUE,IF(EZ27>0,EZ27,EX27*EY27),0) -> 0 | FB27: =20-SUM(EZ27:EZ35) -> 20
EU28: FALSE | EW28: a2 | EX28: =VLOOKUP($F$9,$ER$30:$ES$32,2,FALSE) -> 2 | EY28: =IF(EU28=TRUE,1,0) -> 0 | EZ28: =IF(EU28=TRUE,IF(EZ28>0,EZ28,EX28*EY28),0) -> 0
EU29: FALSE | EW29: a3 | EX29: =VLOOKUP($F$9,$ER$30:$ES$32,2,FALSE) -> 2 | EY29: =IF(EU29=TRUE,1,0) -> 0 | EZ29: =IF(EU29=TRUE,IF(EZ29>0,EZ29,EX29*EY29),0) -> 0
ER30: Puñetazo | ES30: 2 | EU30: FALSE | EW30: a4 | EX30: =VLOOKUP($F$9,$ER$30:$ES$32,2,FALSE) -> 2 | EY30: =IF(EU30=TRUE,1,0) -> 0 | EZ30: =IF(EU30=TRUE,IF(EZ30>0,EZ30,EX30*EY30),0) -> 0
ER31: Espadazo | ES31: 5 | EU31: FALSE | EW31: a5 | EX31: =VLOOKUP($F$9,$ER$30:$ES$32,2,FALSE) -> 2 | EY31: =IF(EU31=TRUE,1,0) -> 0 | EZ31: =IF(EU31=TRUE,IF(EZ31>0,EZ31,EX31*EY31),0) -> 0
ER32: CRÍTICO | ES32: 10 | EU32: FALSE | EW32: a6 | EX32: =VLOOKUP($F$9,$ER$30:$ES$32,2,FALSE) -> 2 | EY32: =IF(EU32=TRUE,1,0) -> 0 | EZ32: =IF(EU32=TRUE,IF(EZ32>0,EZ32,EX32*EY32),0) -> 0 | FO32: FALSE
EU33: FALSE | EW33: a7 | EX33: =VLOOKUP($F$9,$ER$30:$ES$32,2,FALSE) -> 2 | EY33: =IF(EU33=TRUE,1,0) -> 0 | EZ33: =IF(EU33=TRUE,IF(EZ33>0,EZ33,EX33*EY33),0) -> 0
EU34: FALSE | EW34: a8 | EX34: =VLOOKUP($F$9,$ER$30:$ES$32,2,FALSE) -> 2 | EY34: =IF(EU34=TRUE,1,0) -> 0 | EZ34: =IF(EU34=TRUE,IF(EZ34>0,EZ34,EX34*EY34),0) -> 0
EU35: FALSE | EW35: a9 | EX35: =VLOOKUP($F$9,$ER$30:$ES$32,2,FALSE) -> 2 | EY35: =IF(EU35=TRUE,1,0) -> 0 | EZ35: =IF(EU35=TRUE,IF(EZ35>0,EZ35,EX35*EY35),0) -> 0
AQ37: =IF(OR(BZ16<1),"Continuar","")
CD111: 20

Sheet Playa
BM10: Taberna!A1
BO24: Taberna!A1

Sheet Playa2

Sheet Pueblo-Cantina
BF13: CANTINA

Sheet Pueblo

Sheet Cantina
CM26: Cantina-menú'!A1
BB40: º

Sheet Cantina-menú
CM26: Cantina 2'!A1
BB40: º

Sheet Cantina 2
CM26: Cantina!A1
EN29: º
BB40: º
CD90: ZZZ...
